<sdf version='1.11'>
  <model name='mir_250'>
    <link name='base_footprint'>
      <inertial>
        <pose>-0.032078774816343879 0 0.20905530933155239 0 0 0</pose>
        <mass>164.71000000000001</mass>
        <inertia>
          <ixx>2.8005702319734911</ixx>
          <ixy>-0.26127167331259998</ixy>
          <ixz>-0.31289424263857651</ixz>
          <iyy>5.2919115062952491</iyy>
          <iyz>0</iyz>
          <izz>5.2587863170069573</izz>
        </inertia>
      </inertial>
      <collision name='base_footprint_fixed_joint_lump__base_link_collision'>
        <pose>-0.0044850000000000003 0 0 0 0 0</pose>
        <geometry>
          <mesh>
            <scale>1 1 1</scale>
            <uri>model://mir_description/meshes/collision/mir_250_base.stl</uri>
          </mesh>
        </geometry>
        <surface>
          <contact>
            <ode/>
          </contact>
          <friction>
            <ode/>
          </friction>
        </surface>
      </collision>
      <collision name='base_footprint_fixed_joint_lump__back_laser_link_collision_1'>
        <pose>-0.31640000000000001 -0.2064 0.19139999999999999 3.1415926535897931 0 -2.3561944901923448</pose>
        <geometry>
          <mesh>
            <scale>1 1 1</scale>
            <uri>model://mir_description/meshes/visual/sick_lms-100.stl</uri>
          </mesh>
        </geometry>
        <surface>
          <contact>
            <ode/>
          </contact>
          <friction>
            <ode/>
          </friction>
        </surface>
      </collision>
      <collision name='base_footprint_fixed_joint_lump__front_laser_link_collision_2'>
        <pose>0.31640000000000001 0.2064 0.19139999999999999 3.1415926535897931 -6.1629758220391547e-33 0.78539816339744839</pose>
        <geometry>
          <mesh>
            <scale>1 1 1</scale>
            <uri>model://mir_description/meshes/visual/sick_lms-100.stl</uri>
          </mesh>
        </geometry>
        <surface>
          <contact>
            <ode/>
          </contact>
          <friction>
            <ode/>
          </friction>
        </surface>
      </collision>
      <collision name='base_footprint_fixed_joint_lump__power_unit_collision_3'>
        <pose>0 0 0.54499999999999993 0 0 0</pose>
        <geometry>
          <box>
            <size>0.72999999999999998 0.56000000000000005 0.48999999999999999</size>
          </box>
        </geometry>
      </collision>
      <collision name='base_footprint_fixed_joint_lump__ur_base_link_inertia_collision_4'>
        <pose>0.13500000000000001 0 0.79000000000000004 0 0 1.5707963267948959</pose>
        <geometry>
          <mesh>
            <scale>1 1 1</scale>
            <uri>file:///home/t_b/ros2_ws/src/UR-MiR-mobile-manipulator/install/ur_description/share/ur_description/meshes/ur5e/collision/base.stl</uri>
          </mesh>
        </geometry>
      </collision>
      <visual name='base_footprint_fixed_joint_lump__base_link_visual'>
        <pose>-0.0044850000000000003 0 0 0 0 0</pose>
        <geometry>
          <mesh>
            <scale>1 1 1</scale>
            <uri>model://mir_description/meshes/visual/mir_250_base.stl</uri>
          </mesh>
        </geometry>
        <material>
          <script>
            <name>Gazebo/Grey</name>
            <uri>file://media/materials/scripts/gazebo.material</uri>
          </script>
          <diffuse>0.75000006 0.75000006 0.75000006 1</diffuse>
          <ambient>0.75000006 0.75000006 0.75000006 1</ambient>
        </material>
      </visual>
      <visual name='base_footprint_fixed_joint_lump__back_laser_link_visual_1'>
        <pose>-0.31640000000000001 -0.2064 0.19139999999999999 3.1415926535897931 0 -2.3561944901923448</pose>
        <geometry>
          <mesh>
            <scale>1 1 1</scale>
            <uri>model://mir_description/meshes/visual/sick_lms-100.stl</uri>
          </mesh>
        </geometry>
        <material>
          <script>
            <name>Gazebo/FlatBlack</name>
            <uri>file://media/materials/scripts/gazebo.material</uri>
          </script>
          <diffuse>0.125 0.125 0.125 1</diffuse>
          <ambient>0.125 0.125 0.125 1</ambient>
        </material>
      </visual>
      <visual name='base_footprint_fixed_joint_lump__front_laser_link_visual_2'>
        <pose>0.31640000000000001 0.2064 0.19139999999999999 3.1415926535897931 -6.1629758220391547e-33 0.78539816339744839</pose>
        <geometry>
          <mesh>
            <scale>1 1 1</scale>
            <uri>model://mir_description/meshes/visual/sick_lms-100.stl</uri>
          </mesh>
        </geometry>
        <material>
          <script>
            <name>Gazebo/FlatBlack</name>
            <uri>file://media/materials/scripts/gazebo.material</uri>
          </script>
          <diffuse>0.125 0.125 0.125 1</diffuse>
          <ambient>0.125 0.125 0.125 1</ambient>
        </material>
      </visual>
      <visual name='base_footprint_fixed_joint_lump__power_unit_visual_3'>
        <pose>0 0 0.54499999999999993 0 0 0</pose>
        <geometry>
          <box>
            <size>0.72999999999999998 0.56000000000000005 0.48999999999999999</size>
          </box>
        </geometry>
        <material>
          <diffuse>0.75000006 0.75000006 0.75000006 1</diffuse>
          <ambient>0.75000006 0.75000006 0.75000006 1</ambient>
        </material>
      </visual>
      <visual name='base_footprint_fixed_joint_lump__ur_base_link_inertia_visual_4'>
        <pose>0.13500000000000001 0 0.79000000000000004 0 0 1.5707963267948959</pose>
        <geometry>
          <mesh>
            <scale>1 1 1</scale>
            <uri>file:///home/t_b/ros2_ws/src/UR-MiR-mobile-manipulator/install/ur_description/share/ur_description/meshes/ur5e/visual/base.dae</uri>
          </mesh>
        </geometry>
      </visual>
      <sensor name='back_laser_link' type='gpu_lidar'>
        <visualize>false</visualize>
        <update_rate>12.5</update_rate>
        <ray>
          <scan>
            <horizontal>
              <samples>541</samples>
              <resolution>1</resolution>
              <min_angle>-2.0943800000000001</min_angle>
              <max_angle>2.0943800000000001</max_angle>
            </horizontal>
          </scan>
          <range>
            <min>0.050000000000000003</min>
            <max>29</max>
            <resolution>0.01</resolution>
          </range>
          <noise>
            <type>gaussian</type>
            <mean>0</mean>
            <stddev>0.01</stddev>
          </noise>
        </ray>
        <pose>-0.31640000000000001 -0.2064 0.19139999999999999 0 0 -2.3561899999999998</pose>
      </sensor>
      <sensor name='front_laser_link' type='gpu_lidar'>
        <visualize>false</visualize>
        <update_rate>12.5</update_rate>
        <ray>
          <scan>
            <horizontal>
              <samples>541</samples>
              <resolution>1</resolution>
              <min_angle>-2.0943800000000001</min_angle>
              <max_angle>2.0943800000000001</max_angle>
            </horizontal>
          </scan>
          <range>
            <min>0.050000000000000003</min>
            <max>29</max>
            <resolution>0.01</resolution>
          </range>
          <noise>
            <type>gaussian</type>
            <mean>0</mean>
            <stddev>0.01</stddev>
          </noise>
        </ray>
        <pose>0.31640000000000001 0.2064 0.19139999999999999 0 0 0.78539799999999993</pose>
      </sensor>
      <gravity>true</gravity>
      <sensor name='imu_sensor' type='imu'>
        <topic>imu_data</topic>
        <always_on>true</always_on>
        <update_rate>50</update_rate>
        <visualize>true</visualize>
        <imu>
          <angular_velocity>
            <x>
              <noise type='gaussian'>
                <mean>0</mean>
                <stddev>0.00017000000000000001</stddev>
                <bias_mean>7.5000000000000002e-06</bias_mean>
                <bias_stddev>7.9999999999999996e-07</bias_stddev>
              </noise>
            </x>
            <y>
              <noise type='gaussian'>
                <mean>0</mean>
                <stddev>0.00017000000000000001</stddev>
                <bias_mean>7.5000000000000002e-06</bias_mean>
                <bias_stddev>7.9999999999999996e-07</bias_stddev>
              </noise>
            </y>
            <z>
              <noise type='gaussian'>
                <mean>0</mean>
                <stddev>0.00017000000000000001</stddev>
                <bias_mean>7.5000000000000002e-06</bias_mean>
                <bias_stddev>7.9999999999999996e-07</bias_stddev>
              </noise>
            </z>
          </angular_velocity>
          <linear_acceleration>
            <x>
              <noise type='gaussian'>
                <mean>0</mean>
                <stddev>0.00017000000000000001</stddev>
                <bias_mean>0.10000000000000001</bias_mean>
                <bias_stddev>0.001</bias_stddev>
              </noise>
            </x>
            <y>
              <noise type='gaussian'>
                <mean>0</mean>
                <stddev>0.00017000000000000001</stddev>
                <bias_mean>0.10000000000000001</bias_mean>
                <bias_stddev>0.001</bias_stddev>
              </noise>
            </y>
            <z>
              <noise type='gaussian'>
                <mean>0</mean>
                <stddev>0.00017000000000000001</stddev>
                <bias_mean>0.10000000000000001</bias_mean>
                <bias_stddev>0.001</bias_stddev>
              </noise>
            </z>
          </linear_acceleration>
        </imu>
        <pose>0 0 0.25 0 0 0</pose>
      </sensor>
    </link>
    <joint name='bl_caster_rotation_joint' type='revolute'>
      <pose relative_to='base_footprint'>-0.29599999999999999 0.188 0.1565 0 0 0</pose>
      <parent>base_footprint</parent>
      <child>bl_caster_rotation_link</child>
      <axis>
        <xyz>0 0 1</xyz>
        <limit>
          <lower>-inf</lower>
          <upper>inf</upper>
        </limit>
        <dynamics>
          <damping>0</damping>
          <friction>0</friction>
          <spring_reference>0</spring_reference>
          <spring_stiffness>0</spring_stiffness>
        </dynamics>
      </axis>
    </joint>
    <link name='bl_caster_rotation_link'>
      <pose relative_to='bl_caster_rotation_joint'>0 0 0 0 0 0</pose>
      <inertial>
        <pose>0 0 -0.042500000044000001 0.41887903200000004 2.7755575615628914e-17 1.5707963267948959</pose>
        <mass>0.30975390190000002</mass>
        <inertia>
          <ixx>0.00058445179780000005</ixx>
          <ixy>0</ixy>
          <ixz>0</ixz>
          <iyy>0.00052872551237000001</iyy>
          <iyz>0</iyz>
          <izz>0.00017923555073999999</izz>
        </inertia>
      </inertial>
      <collision name='bl_caster_rotation_link_collision'>
        <pose>0 0 0 0 0 0</pose>
        <geometry>
          <mesh>
            <scale>1 1 1</scale>
            <uri>model://mir_description/meshes/collision/caster_wheel_base.stl</uri>
          </mesh>
        </geometry>
        <surface>
          <contact>
            <ode/>
          </contact>
          <friction>
            <ode/>
          </friction>
        </surface>
      </collision>
      <visual name='bl_caster_rotation_link_visual'>
        <pose>0 0 0 0 0 0</pose>
        <geometry>
          <mesh>
            <scale>1 1 1</scale>
            <uri>model://mir_description/meshes/visual/caster_wheel_base.stl</uri>
          </mesh>
        </geometry>
        <material>
          <script>
            <name>Gazebo/Grey</name>
            <uri>file://media/materials/scripts/gazebo.material</uri>
          </script>
          <diffuse>0.987500012 1 1 1</diffuse>
          <ambient>0.987500012 1 1 1</ambient>
        </material>
      </visual>
    </link>
    <joint name='bl_caster_wheel_joint' type='revolute'>
      <pose relative_to='bl_caster_rotation_link'>-0.038199999999999998 0 -0.094 0 0 0</pose>
      <parent>bl_caster_rotation_link</parent>
      <child>bl_caster_wheel_link</child>
      <axis>
        <xyz>0 1 0</xyz>
        <limit>
          <lower>-inf</lower>
          <upper>inf</upper>
        </limit>
        <dynamics>
          <spring_reference>0</spring_reference>
          <spring_stiffness>0</spring_stiffness>
        </dynamics>
      </axis>
    </joint>
    <link name='bl_caster_wheel_link'>
      <pose relative_to='bl_caster_wheel_joint'>0 0 0 0 0 0</pose>
      <inertial>
        <pose>0 0 0 1.5707963267948959 0 0</pose>
        <mass>1</mass>
        <inertia>
          <ixx>0.001061895408575</ixx>
          <ixy>0</ixy>
          <ixz>0</ixz>
          <iyy>0.001061895408575</iyy>
          <iyz>0</iyz>
          <izz>0.001953125</izz>
        </inertia>
      </inertial>
      <collision name='bl_caster_wheel_link_collision'>
        <pose>0 0 0 1.5707963267948959 0 0</pose>
        <geometry>
          <cylinder>
            <length>1.0000000000000001e-05</length>
            <radius>0.0625</radius>
          </cylinder>
        </geometry>
        <surface>
          <friction>
            <ode>
              <mu>1</mu>
              <mu2>1</mu2>
              <fdir1>0 0 1</fdir1>
              <slip1>0</slip1>
              <slip2>0.5</slip2>
            </ode>
          </friction>
          <contact>
            <ode>
              <kp>100000000</kp>
              <min_depth>0</min_depth>
            </ode>
          </contact>
        </surface>
      </collision>
      <visual name='bl_caster_wheel_link_visual'>
        <pose>0 0 0 0 0 0</pose>
        <geometry>
          <mesh>
            <scale>1 1 1</scale>
            <uri>model://mir_description/meshes/visual/wheel.stl</uri>
          </mesh>
        </geometry>
        <material>
          <script>
            <name>Gazebo/DarkGrey</name>
            <uri>file://media/materials/scripts/gazebo.material</uri>
          </script>
          <diffuse>0.37500003 0.37500003 0.37500003 1</diffuse>
          <ambient>0.37500003 0.37500003 0.37500003 1</ambient>
        </material>
      </visual>
    </link>
    <joint name='br_caster_rotation_joint' type='revolute'>
      <pose relative_to='base_footprint'>-0.29599999999999999 -0.188 0.1565 0 0 0</pose>
      <parent>base_footprint</parent>
      <child>br_caster_rotation_link</child>
      <axis>
        <xyz>0 0 1</xyz>
        <limit>
          <lower>-inf</lower>
          <upper>inf</upper>
        </limit>
        <dynamics>
          <damping>0</damping>
          <friction>0</friction>
          <spring_reference>0</spring_reference>
          <spring_stiffness>0</spring_stiffness>
        </dynamics>
      </axis>
    </joint>
    <link name='br_caster_rotation_link'>
      <pose relative_to='br_caster_rotation_joint'>0 0 0 0 0 0</pose>
      <inertial>
        <pose>0 0 -0.042500000044000001 0.41887903200000004 2.7755575615628914e-17 1.5707963267948959</pose>
        <mass>0.30975390190000002</mass>
        <inertia>
          <ixx>0.00058445179780000005</ixx>
          <ixy>0</ixy>
          <ixz>0</ixz>
          <iyy>0.00052872551237000001</iyy>
          <iyz>0</iyz>
          <izz>0.00017923555073999999</izz>
        </inertia>
      </inertial>
      <collision name='br_caster_rotation_link_collision'>
        <pose>0 0 0 0 0 0</pose>
        <geometry>
          <mesh>
            <scale>1 1 1</scale>
            <uri>model://mir_description/meshes/collision/caster_wheel_base.stl</uri>
          </mesh>
        </geometry>
        <surface>
          <contact>
            <ode/>
          </contact>
          <friction>
            <ode/>
          </friction>
        </surface>
      </collision>
      <visual name='br_caster_rotation_link_visual'>
        <pose>0 0 0 0 0 0</pose>
        <geometry>
          <mesh>
            <scale>1 1 1</scale>
            <uri>model://mir_description/meshes/visual/caster_wheel_base.stl</uri>
          </mesh>
        </geometry>
        <material>
          <script>
            <name>Gazebo/Grey</name>
            <uri>file://media/materials/scripts/gazebo.material</uri>
          </script>
          <diffuse>0.987500012 1 1 1</diffuse>
          <ambient>0.987500012 1 1 1</ambient>
        </material>
      </visual>
    </link>
    <joint name='br_caster_wheel_joint' type='revolute'>
      <pose relative_to='br_caster_rotation_link'>-0.038199999999999998 0 -0.094 0 0 0</pose>
      <parent>br_caster_rotation_link</parent>
      <child>br_caster_wheel_link</child>
      <axis>
        <xyz>0 1 0</xyz>
        <limit>
          <lower>-inf</lower>
          <upper>inf</upper>
        </limit>
        <dynamics>
          <spring_reference>0</spring_reference>
          <spring_stiffness>0</spring_stiffness>
        </dynamics>
      </axis>
    </joint>
    <link name='br_caster_wheel_link'>
      <pose relative_to='br_caster_wheel_joint'>0 0 0 0 0 0</pose>
      <inertial>
        <pose>0 0 0 1.5707963267948959 0 0</pose>
        <mass>1</mass>
        <inertia>
          <ixx>0.001061895408575</ixx>
          <ixy>0</ixy>
          <ixz>0</ixz>
          <iyy>0.001061895408575</iyy>
          <iyz>0</iyz>
          <izz>0.001953125</izz>
        </inertia>
      </inertial>
      <collision name='br_caster_wheel_link_collision'>
        <pose>0 0 0 1.5707963267948959 0 0</pose>
        <geometry>
          <cylinder>
            <length>1.0000000000000001e-05</length>
            <radius>0.0625</radius>
          </cylinder>
        </geometry>
        <surface>
          <friction>
            <ode>
              <mu>1</mu>
              <mu2>1</mu2>
              <fdir1>0 0 1</fdir1>
              <slip1>0</slip1>
              <slip2>0.5</slip2>
            </ode>
          </friction>
          <contact>
            <ode>
              <kp>100000000</kp>
              <min_depth>0</min_depth>
            </ode>
          </contact>
        </surface>
      </collision>
      <visual name='br_caster_wheel_link_visual'>
        <pose>0 0 0 0 0 0</pose>
        <geometry>
          <mesh>
            <scale>1 1 1</scale>
            <uri>model://mir_description/meshes/visual/wheel.stl</uri>
          </mesh>
        </geometry>
        <material>
          <script>
            <name>Gazebo/DarkGrey</name>
            <uri>file://media/materials/scripts/gazebo.material</uri>
          </script>
          <diffuse>0.37500003 0.37500003 0.37500003 1</diffuse>
          <ambient>0.37500003 0.37500003 0.37500003 1</ambient>
        </material>
      </visual>
    </link>
    <joint name='fl_caster_rotation_joint' type='revolute'>
      <pose relative_to='base_footprint'>0.30370000000000003 0.188 0.1565 0 0 0</pose>
      <parent>base_footprint</parent>
      <child>fl_caster_rotation_link</child>
      <axis>
        <xyz>0 0 1</xyz>
        <limit>
          <lower>-inf</lower>
          <upper>inf</upper>
        </limit>
        <dynamics>
          <damping>0</damping>
          <friction>0</friction>
          <spring_reference>0</spring_reference>
          <spring_stiffness>0</spring_stiffness>
        </dynamics>
      </axis>
    </joint>
    <link name='fl_caster_rotation_link'>
      <pose relative_to='fl_caster_rotation_joint'>0 0 0 0 0 0</pose>
      <inertial>
        <pose>0 0 -0.042500000044000001 0.41887903200000004 2.7755575615628914e-17 1.5707963267948959</pose>
        <mass>0.30975390190000002</mass>
        <inertia>
          <ixx>0.00058445179780000005</ixx>
          <ixy>0</ixy>
          <ixz>0</ixz>
          <iyy>0.00052872551237000001</iyy>
          <iyz>0</iyz>
          <izz>0.00017923555073999999</izz>
        </inertia>
      </inertial>
      <collision name='fl_caster_rotation_link_collision'>
        <pose>0 0 0 0 0 0</pose>
        <geometry>
          <mesh>
            <scale>1 1 1</scale>
            <uri>model://mir_description/meshes/collision/caster_wheel_base.stl</uri>
          </mesh>
        </geometry>
        <surface>
          <contact>
            <ode/>
          </contact>
          <friction>
            <ode/>
          </friction>
        </surface>
      </collision>
      <visual name='fl_caster_rotation_link_visual'>
        <pose>0 0 0 0 0 0</pose>
        <geometry>
          <mesh>
            <scale>1 1 1</scale>
            <uri>model://mir_description/meshes/visual/caster_wheel_base.stl</uri>
          </mesh>
        </geometry>
        <material>
          <script>
            <name>Gazebo/Grey</name>
            <uri>file://media/materials/scripts/gazebo.material</uri>
          </script>
          <diffuse>0.987500012 1 1 1</diffuse>
          <ambient>0.987500012 1 1 1</ambient>
        </material>
      </visual>
    </link>
    <joint name='fl_caster_wheel_joint' type='revolute'>
      <pose relative_to='fl_caster_rotation_link'>-0.038199999999999998 0 -0.094 0 0 0</pose>
      <parent>fl_caster_rotation_link</parent>
      <child>fl_caster_wheel_link</child>
      <axis>
        <xyz>0 1 0</xyz>
        <limit>
          <lower>-inf</lower>
          <upper>inf</upper>
        </limit>
        <dynamics>
          <spring_reference>0</spring_reference>
          <spring_stiffness>0</spring_stiffness>
        </dynamics>
      </axis>
    </joint>
    <link name='fl_caster_wheel_link'>
      <pose relative_to='fl_caster_wheel_joint'>0 0 0 0 0 0</pose>
      <inertial>
        <pose>0 0 0 1.5707963267948959 0 0</pose>
        <mass>1</mass>
        <inertia>
          <ixx>0.001061895408575</ixx>
          <ixy>0</ixy>
          <ixz>0</ixz>
          <iyy>0.001061895408575</iyy>
          <iyz>0</iyz>
          <izz>0.001953125</izz>
        </inertia>
      </inertial>
      <collision name='fl_caster_wheel_link_collision'>
        <pose>0 0 0 1.5707963267948959 0 0</pose>
        <geometry>
          <cylinder>
            <length>1.0000000000000001e-05</length>
            <radius>0.0625</radius>
          </cylinder>
        </geometry>
        <surface>
          <friction>
            <ode>
              <mu>1</mu>
              <mu2>1</mu2>
              <fdir1>0 0 1</fdir1>
              <slip1>0</slip1>
              <slip2>0.5</slip2>
            </ode>
          </friction>
          <contact>
            <ode>
              <kp>100000000</kp>
              <min_depth>0</min_depth>
            </ode>
          </contact>
        </surface>
      </collision>
      <visual name='fl_caster_wheel_link_visual'>
        <pose>0 0 0 0 0 0</pose>
        <geometry>
          <mesh>
            <scale>1 1 1</scale>
            <uri>model://mir_description/meshes/visual/wheel.stl</uri>
          </mesh>
        </geometry>
        <material>
          <script>
            <name>Gazebo/DarkGrey</name>
            <uri>file://media/materials/scripts/gazebo.material</uri>
          </script>
          <diffuse>0.37500003 0.37500003 0.37500003 1</diffuse>
          <ambient>0.37500003 0.37500003 0.37500003 1</ambient>
        </material>
      </visual>
    </link>
    <joint name='fr_caster_rotation_joint' type='revolute'>
      <pose relative_to='base_footprint'>0.30370000000000003 -0.188 0.1565 0 0 0</pose>
      <parent>base_footprint</parent>
      <child>fr_caster_rotation_link</child>
      <axis>
        <xyz>0 0 1</xyz>
        <limit>
          <lower>-inf</lower>
          <upper>inf</upper>
        </limit>
        <dynamics>
          <damping>0</damping>
          <friction>0</friction>
          <spring_reference>0</spring_reference>
          <spring_stiffness>0</spring_stiffness>
        </dynamics>
      </axis>
    </joint>
    <link name='fr_caster_rotation_link'>
      <pose relative_to='fr_caster_rotation_joint'>0 0 0 0 0 0</pose>
      <inertial>
        <pose>0 0 -0.042500000044000001 0.41887903200000004 2.7755575615628914e-17 1.5707963267948959</pose>
        <mass>0.30975390190000002</mass>
        <inertia>
          <ixx>0.00058445179780000005</ixx>
          <ixy>0</ixy>
          <ixz>0</ixz>
          <iyy>0.00052872551237000001</iyy>
          <iyz>0</iyz>
          <izz>0.00017923555073999999</izz>
        </inertia>
      </inertial>
      <collision name='fr_caster_rotation_link_collision'>
        <pose>0 0 0 0 0 0</pose>
        <geometry>
          <mesh>
            <scale>1 1 1</scale>
            <uri>model://mir_description/meshes/collision/caster_wheel_base.stl</uri>
          </mesh>
        </geometry>
        <surface>
          <contact>
            <ode/>
          </contact>
          <friction>
            <ode/>
          </friction>
        </surface>
      </collision>
      <visual name='fr_caster_rotation_link_visual'>
        <pose>0 0 0 0 0 0</pose>
        <geometry>
          <mesh>
            <scale>1 1 1</scale>
            <uri>model://mir_description/meshes/visual/caster_wheel_base.stl</uri>
          </mesh>
        </geometry>
        <material>
          <script>
            <name>Gazebo/Grey</name>
            <uri>file://media/materials/scripts/gazebo.material</uri>
          </script>
          <diffuse>0.987500012 1 1 1</diffuse>
          <ambient>0.987500012 1 1 1</ambient>
        </material>
      </visual>
    </link>
    <joint name='fr_caster_wheel_joint' type='revolute'>
      <pose relative_to='fr_caster_rotation_link'>-0.038199999999999998 0 -0.094 0 0 0</pose>
      <parent>fr_caster_rotation_link</parent>
      <child>fr_caster_wheel_link</child>
      <axis>
        <xyz>0 1 0</xyz>
        <limit>
          <lower>-inf</lower>
          <upper>inf</upper>
        </limit>
        <dynamics>
          <spring_reference>0</spring_reference>
          <spring_stiffness>0</spring_stiffness>
        </dynamics>
      </axis>
    </joint>
    <link name='fr_caster_wheel_link'>
      <pose relative_to='fr_caster_wheel_joint'>0 0 0 0 0 0</pose>
      <inertial>
        <pose>0 0 0 1.5707963267948959 0 0</pose>
        <mass>1</mass>
        <inertia>
          <ixx>0.001061895408575</ixx>
          <ixy>0</ixy>
          <ixz>0</ixz>
          <iyy>0.001061895408575</iyy>
          <iyz>0</iyz>
          <izz>0.001953125</izz>
        </inertia>
      </inertial>
      <collision name='fr_caster_wheel_link_collision'>
        <pose>0 0 0 1.5707963267948959 0 0</pose>
        <geometry>
          <cylinder>
            <length>1.0000000000000001e-05</length>
            <radius>0.0625</radius>
          </cylinder>
        </geometry>
        <surface>
          <friction>
            <ode>
              <mu>1</mu>
              <mu2>1</mu2>
              <fdir1>0 0 1</fdir1>
              <slip1>0</slip1>
              <slip2>0.5</slip2>
            </ode>
          </friction>
          <contact>
            <ode>
              <kp>100000000</kp>
              <min_depth>0</min_depth>
            </ode>
          </contact>
        </surface>
      </collision>
      <visual name='fr_caster_wheel_link_visual'>
        <pose>0 0 0 0 0 0</pose>
        <geometry>
          <mesh>
            <scale>1 1 1</scale>
            <uri>model://mir_description/meshes/visual/wheel.stl</uri>
          </mesh>
        </geometry>
        <material>
          <script>
            <name>Gazebo/DarkGrey</name>
            <uri>file://media/materials/scripts/gazebo.material</uri>
          </script>
          <diffuse>0.37500003 0.37500003 0.37500003 1</diffuse>
          <ambient>0.37500003 0.37500003 0.37500003 1</ambient>
        </material>
      </visual>
    </link>
    <joint name='left_wheel_joint' type='revolute'>
      <pose relative_to='base_footprint'>0 0.20150000000000001 0.10000000000000001 0 0 0</pose>
      <parent>base_footprint</parent>
      <child>left_wheel_link</child>
      <axis>
        <xyz>0 1 0</xyz>
        <limit>
          <effort>250</effort>
          <velocity>20</velocity>
          <lower>-inf</lower>
          <upper>inf</upper>
        </limit>
        <dynamics>
          <spring_reference>0</spring_reference>
          <spring_stiffness>0</spring_stiffness>
        </dynamics>
      </axis>
    </joint>
    <link name='left_wheel_link'>
      <pose relative_to='left_wheel_joint'>0 0 0 0 0 0</pose>
      <inertial>
        <pose>0 0 0 1.5707963267948959 0 0</pose>
        <mass>1</mass>
        <inertia>
          <ixx>0.0026203322852000012</ixx>
          <ixy>0</ixy>
          <ixz>0</ixz>
          <iyy>0.0026203322852000012</iyy>
          <iyz>0</iyz>
          <izz>0.005000000000000001</izz>
        </inertia>
      </inertial>
      <collision name='left_wheel_link_collision'>
        <pose>0 0 0 1.5707963267948959 0 0</pose>
        <geometry>
          <cylinder>
            <length>0.037999999999999999</length>
            <radius>0.10000000000000001</radius>
          </cylinder>
        </geometry>
        <surface>
          <friction>
            <ode>
              <mu>300</mu>
              <mu2>300</mu2>
              <fdir1>0 0 1</fdir1>
            </ode>
            <torsional>
              <coefficient>300</coefficient>
              <use_patch_radius>false</use_patch_radius>
              <surface_radius>0.10000000000000001</surface_radius>
            </torsional>
          </friction>
          <contact>
            <ode>
              <min_depth>0.001</min_depth>
            </ode>
          </contact>
        </surface>
      </collision>
      <visual name='left_wheel_link_visual'>
        <pose>0 0 0 1.5707963267948959 0 0</pose>
        <geometry>
          <cylinder>
            <length>0.037999999999999999</length>
            <radius>0.10000000000000001</radius>
          </cylinder>
        </geometry>
        <material>
          <script>
            <name>Gazebo/DarkGrey</name>
            <uri>file://media/materials/scripts/gazebo.material</uri>
          </script>
          <diffuse>0.37500003 0.37500003 0.37500003 1</diffuse>
          <ambient>0.37500003 0.37500003 0.37500003 1</ambient>
        </material>
      </visual>
    </link>
    <joint name='right_wheel_joint' type='revolute'>
      <pose relative_to='base_footprint'>0 -0.20150000000000001 0.10000000000000001 0 0 0</pose>
      <parent>base_footprint</parent>
      <child>right_wheel_link</child>
      <axis>
        <xyz>0 1 0</xyz>
        <limit>
          <effort>250</effort>
          <velocity>20</velocity>
          <lower>-inf</lower>
          <upper>inf</upper>
        </limit>
        <dynamics>
          <spring_reference>0</spring_reference>
          <spring_stiffness>0</spring_stiffness>
        </dynamics>
      </axis>
    </joint>
    <link name='right_wheel_link'>
      <pose relative_to='right_wheel_joint'>0 0 0 0 0 0</pose>
      <inertial>
        <pose>0 0 0 1.5707963267948959 0 0</pose>
        <mass>1</mass>
        <inertia>
          <ixx>0.0026203322852000012</ixx>
          <ixy>0</ixy>
          <ixz>0</ixz>
          <iyy>0.0026203322852000012</iyy>
          <iyz>0</iyz>
          <izz>0.005000000000000001</izz>
        </inertia>
      </inertial>
      <collision name='right_wheel_link_collision'>
        <pose>0 0 0 1.5707963267948959 0 0</pose>
        <geometry>
          <cylinder>
            <length>0.037999999999999999</length>
            <radius>0.10000000000000001</radius>
          </cylinder>
        </geometry>
        <surface>
          <friction>
            <ode>
              <mu>300</mu>
              <mu2>300</mu2>
              <fdir1>0 0 1</fdir1>
            </ode>
            <torsional>
              <coefficient>300</coefficient>
              <use_patch_radius>false</use_patch_radius>
              <surface_radius>0.10000000000000001</surface_radius>
            </torsional>
          </friction>
          <contact>
            <ode>
              <min_depth>0.001</min_depth>
            </ode>
          </contact>
        </surface>
      </collision>
      <visual name='right_wheel_link_visual'>
        <pose>0 0 0 1.5707963267948959 0 0</pose>
        <geometry>
          <cylinder>
            <length>0.037999999999999999</length>
            <radius>0.10000000000000001</radius>
          </cylinder>
        </geometry>
        <material>
          <script>
            <name>Gazebo/DarkGrey</name>
            <uri>file://media/materials/scripts/gazebo.material</uri>
          </script>
          <diffuse>0.37500003 0.37500003 0.37500003 1</diffuse>
          <ambient>0.37500003 0.37500003 0.37500003 1</ambient>
        </material>
      </visual>
    </link>
    <joint name='ur_shoulder_pan_joint' type='revolute'>
      <pose relative_to='base_footprint'>0.13500000000000001 0 0.95250000000000001 0 0 -1.570796326794897</pose>
      <parent>base_footprint</parent>
      <child>ur_shoulder_link</child>
      <axis>
        <xyz>0 0 1</xyz>
        <limit>
          <lower>-6.2831853071795862</lower>
          <upper>6.2831853071795862</upper>
          <effort>150</effort>
          <velocity>3.1415926535897931</velocity>
        </limit>
        <dynamics>
          <damping>0</damping>
          <friction>0</friction>
          <spring_reference>0</spring_reference>
          <spring_stiffness>0</spring_stiffness>
        </dynamics>
      </axis>
    </joint>
    <link name='ur_shoulder_link'>
      <pose relative_to='ur_shoulder_pan_joint'>0 0 0 0 0 0</pose>
      <inertial>
        <pose>0 0 0 0 0 0</pose>
        <mass>0.01</mass>
        <inertia>
          <ixx>2.7749988899999999e-05</ixx>
          <ixy>0</ixy>
          <ixz>0</ixz>
          <iyy>2.7749988899999999e-05</iyy>
          <iyz>0</iyz>
          <izz>1.8e-05</izz>
        </inertia>
      </inertial>
      <collision name='ur_shoulder_link_collision'>
        <pose>0 0 0 0 0 3.1415926535897931</pose>
        <geometry>
          <mesh>
            <scale>1 1 1</scale>
            <uri>file:///home/t_b/ros2_ws/src/UR-MiR-mobile-manipulator/install/ur_description/share/ur_description/meshes/ur5e/collision/shoulder.stl</uri>
          </mesh>
        </geometry>
      </collision>
      <visual name='ur_shoulder_link_visual'>
        <pose>0 0 0 0 0 3.1415926535897931</pose>
        <geometry>
          <mesh>
            <scale>1 1 1</scale>
            <uri>file:///home/t_b/ros2_ws/src/UR-MiR-mobile-manipulator/install/ur_description/share/ur_description/meshes/ur5e/visual/shoulder.dae</uri>
          </mesh>
        </geometry>
      </visual>
    </link>
    <joint name='ur_shoulder_lift_joint' type='revolute'>
      <pose relative_to='ur_shoulder_link'>0 0 0 1.5707963270000003 0 0</pose>
      <parent>ur_shoulder_link</parent>
      <child>ur_upper_arm_link</child>
      <axis>
        <xyz>0 0 1</xyz>
        <limit>
          <lower>-6.2831853071795862</lower>
          <upper>6.2831853071795862</upper>
          <effort>150</effort>
          <velocity>3.1415926535897931</velocity>
        </limit>
        <dynamics>
          <damping>0</damping>
          <friction>0</friction>
          <spring_reference>0</spring_reference>
          <spring_stiffness>0</spring_stiffness>
        </dynamics>
      </axis>
    </joint>
    <link name='ur_upper_arm_link'>
      <pose relative_to='ur_shoulder_lift_joint'>0 0 0 0 0 0</pose>
      <inertial>
        <pose>-0.21249999999999999 0 0.13800000000000001 0 1.5707963267948966 0</pose>
        <mass>0.01</mass>
        <inertia>
          <ixx>0.000159520769525</ixx>
          <ixy>0</ixy>
          <ixz>0</ixz>
          <iyy>0.000159520769525</iyy>
          <iyz>0</iyz>
          <izz>1.8e-05</izz>
        </inertia>
      </inertial>
      <collision name='ur_upper_arm_link_collision'>
        <pose>0 0 0.13800000000000001 1.5707963267948959 5.5511151231257827e-17 -1.5707963267948959</pose>
        <geometry>
          <mesh>
            <scale>1 1 1</scale>
            <uri>file:///home/t_b/ros2_ws/src/UR-MiR-mobile-manipulator/install/ur_description/share/ur_description/meshes/ur5e/collision/upperarm.stl</uri>
          </mesh>
        </geometry>
      </collision>
      <visual name='ur_upper_arm_link_visual'>
        <pose>0 0 0.13800000000000001 1.5707963267948959 5.5511151231257827e-17 -1.5707963267948959</pose>
        <geometry>
          <mesh>
            <scale>1 1 1</scale>
            <uri>file:///home/t_b/ros2_ws/src/UR-MiR-mobile-manipulator/install/ur_description/share/ur_description/meshes/ur5e/visual/upperarm.dae</uri>
          </mesh>
        </geometry>
      </visual>
    </link>
    <joint name='ur_elbow_joint' type='revolute'>
      <pose relative_to='ur_upper_arm_link'>-0.42499999999999999 0 0 0 0 0</pose>
      <parent>ur_upper_arm_link</parent>
      <child>ur_forearm_link</child>
      <axis>
        <xyz>0 0 1</xyz>
        <limit>
          <lower>-3.1415926535897931</lower>
          <upper>3.1415926535897931</upper>
          <effort>150</effort>
          <velocity>3.1415926535897931</velocity>
        </limit>
        <dynamics>
          <damping>0</damping>
          <friction>0</friction>
          <spring_reference>0</spring_reference>
          <spring_stiffness>0</spring_stiffness>
        </dynamics>
      </axis>
    </joint>
    <link name='ur_forearm_link'>
      <pose relative_to='ur_elbow_joint'>0 0 0 0 0 0</pose>
      <inertial>
        <pose>-0.1961 0 0.0070000000000000001 0 1.5707963267948966 0</pose>
        <mass>0.01</mass>
        <inertia>
          <ixx>0.00013718397845971999</ixx>
          <ixy>0</ixy>
          <ixz>0</ixz>
          <iyy>0.00013718397845971999</iyy>
          <iyz>0</iyz>
          <izz>1.8e-05</izz>
        </inertia>
      </inertial>
      <collision name='ur_forearm_link_collision'>
        <pose>0 0 0.0070000000000000001 1.5707963267948959 5.5511151231257827e-17 -1.5707963267948959</pose>
        <geometry>
          <mesh>
            <scale>1 1 1</scale>
            <uri>file:///home/t_b/ros2_ws/src/UR-MiR-mobile-manipulator/install/ur_description/share/ur_description/meshes/ur5e/collision/forearm.stl</uri>
          </mesh>
        </geometry>
      </collision>
      <visual name='ur_forearm_link_visual'>
        <pose>0 0 0.0070000000000000001 1.5707963267948959 5.5511151231257827e-17 -1.5707963267948959</pose>
        <geometry>
          <mesh>
            <scale>1 1 1</scale>
            <uri>file:///home/t_b/ros2_ws/src/UR-MiR-mobile-manipulator/install/ur_description/share/ur_description/meshes/ur5e/visual/forearm.dae</uri>
          </mesh>
        </geometry>
      </visual>
    </link>
    <joint name='ur_wrist_1_joint' type='revolute'>
      <pose relative_to='ur_forearm_link'>-0.39219999999999999 0 0.1333 0 0 0</pose>
      <parent>ur_forearm_link</parent>
      <child>ur_wrist_1_link</child>
      <axis>
        <xyz>0 0 1</xyz>
        <limit>
          <lower>-6.2831853071795862</lower>
          <upper>6.2831853071795862</upper>
          <effort>28</effort>
          <velocity>3.1415926535897931</velocity>
        </limit>
        <dynamics>
          <damping>0</damping>
          <friction>0</friction>
          <spring_reference>0</spring_reference>
          <spring_stiffness>0</spring_stiffness>
        </dynamics>
      </axis>
    </joint>
    <link name='ur_wrist_1_link'>
      <pose relative_to='ur_wrist_1_joint'>0 0 0 0 0 0</pose>
      <inertial>
        <pose>0 0 0 0 0 0</pose>
        <mass>0.01</mass>
        <inertia>
          <ixx>2.0999991600000001e-05</ixx>
          <ixy>0</ixy>
          <ixz>0</ixz>
          <iyy>2.0999991600000001e-05</iyy>
          <iyz>0</iyz>
          <izz>1.8e-05</izz>
        </inertia>
      </inertial>
      <collision name='ur_wrist_1_link_collision'>
        <pose>0 0 -0.127 1.5707963267948959 0 0</pose>
        <geometry>
          <mesh>
            <scale>1 1 1</scale>
            <uri>file:///home/t_b/ros2_ws/src/UR-MiR-mobile-manipulator/install/ur_description/share/ur_description/meshes/ur5e/collision/wrist1.stl</uri>
          </mesh>
        </geometry>
      </collision>
      <visual name='ur_wrist_1_link_visual'>
        <pose>0 0 -0.127 1.5707963267948959 0 0</pose>
        <geometry>
          <mesh>
            <scale>1 1 1</scale>
            <uri>file:///home/t_b/ros2_ws/src/UR-MiR-mobile-manipulator/install/ur_description/share/ur_description/meshes/ur5e/visual/wrist1.dae</uri>
          </mesh>
        </geometry>
      </visual>
    </link>
    <joint name='ur_wrist_2_joint' type='revolute'>
      <pose relative_to='ur_wrist_1_link'>0 -0.099699999999999997 -2.0448811822978519e-11 1.5707963270000003 0 0</pose>
      <parent>ur_wrist_1_link</parent>
      <child>ur_wrist_2_link</child>
      <axis>
        <xyz>0 0 1</xyz>
        <limit>
          <lower>-6.2831853071795862</lower>
          <upper>6.2831853071795862</upper>
          <effort>28</effort>
          <velocity>3.1415926535897931</velocity>
        </limit>
        <dynamics>
          <damping>0</damping>
          <friction>0</friction>
          <spring_reference>0</spring_reference>
          <spring_stiffness>0</spring_stiffness>
        </dynamics>
      </axis>
    </joint>
    <link name='ur_wrist_2_link'>
      <pose relative_to='ur_wrist_2_joint'>0 0 0 0 0 0</pose>
      <inertial>
        <pose>0 0 0 0 0 0</pose>
        <mass>0.01</mass>
        <inertia>
          <ixx>2.0999991600000001e-05</ixx>
          <ixy>0</ixy>
          <ixz>0</ixz>
          <iyy>2.0999991600000001e-05</iyy>
          <iyz>0</iyz>
          <izz>1.8e-05</izz>
        </inertia>
      </inertial>
      <collision name='ur_wrist_2_link_collision'>
        <pose>0 0 -0.099699999999999997 0 0 0</pose>
        <geometry>
          <mesh>
            <scale>1 1 1</scale>
            <uri>file:///home/t_b/ros2_ws/src/UR-MiR-mobile-manipulator/install/ur_description/share/ur_description/meshes/ur5e/collision/wrist2.stl</uri>
          </mesh>
        </geometry>
      </collision>
      <visual name='ur_wrist_2_link_visual'>
        <pose>0 0 -0.099699999999999997 0 0 0</pose>
        <geometry>
          <mesh>
            <scale>1 1 1</scale>
            <uri>file:///home/t_b/ros2_ws/src/UR-MiR-mobile-manipulator/install/ur_description/share/ur_description/meshes/ur5e/visual/wrist2.dae</uri>
          </mesh>
        </geometry>
      </visual>
    </link>
    <joint name='ur_wrist_3_joint' type='revolute'>
      <pose relative_to='ur_wrist_2_link'>0 0.099599999999999994 -2.0428301480126979e-11 -1.5707963270000003 1.2246467991473527e-16 -1.224646799147353e-16</pose>
      <parent>ur_wrist_2_link</parent>
      <child>ur_wrist_3_link</child>
      <axis>
        <xyz>0 0 1</xyz>
        <limit>
          <lower>-6.2831853071795862</lower>
          <upper>6.2831853071795862</upper>
          <effort>28</effort>
          <velocity>3.1415926535897931</velocity>
        </limit>
        <dynamics>
          <damping>0</damping>
          <friction>0</friction>
          <spring_reference>0</spring_reference>
          <spring_stiffness>0</spring_stiffness>
        </dynamics>
      </axis>
    </joint>
    <link name='ur_wrist_3_link'>
      <pose relative_to='ur_wrist_3_joint'>0 0 0 0 0 0</pose>
      <inertial>
        <pose>-0.01536585365853657 -0.064536585365853646 0.024075609756097561 0 0 0</pose>
        <mass>0.08199999999999999</mass>
        <inertia>
          <ixx>0.00057676999769128471</ixx>
          <ixy>-1.129390243902432e-05</ixy>
          <ixz>8.2207317073170671e-06</ixz>
          <iyy>3.6963888837626078e-05</iyy>
          <iyz>3.4527073170731698e-05</iyz>
          <izz>6.1035907634146471e-05</izz>
        </inertia>
      </inertial>
      <collision name='ur_wrist_3_link_collision'>
        <pose>0 0 -0.098900000000000002 1.5707963267948959 0 0</pose>
        <geometry>
          <mesh>
            <scale>1 1 1</scale>
            <uri>file:///home/t_b/ros2_ws/src/UR-MiR-mobile-manipulator/install/ur_description/share/ur_description/meshes/ur5e/collision/wrist3.stl</uri>
          </mesh>
        </geometry>
      </collision>
      <collision name='ur_wrist_3_link_fixed_joint_lump__camera_mount_collision_1'>
        <pose>0.049999999999999989 0.029999999999999999 0.035000000000000017 -1.570796326794897 1.876254158470614e-16 -3.1415926535897931</pose>
        <geometry>
          <mesh>
            <scale>0.001 0.001 0.001</scale>
            <uri>model://mir_description/meshes/collision/D435i_mounted.STL</uri>
          </mesh>
        </geometry>
      </collision>
      <collision name='ur_wrist_3_link_fixed_joint_lump__realsense_link_collision_2'>
        <pose>1.387778780781446e-17 -0.07350000000000001 0.030599999999999988 1.570796326794897 -1.5707963267948966 0</pose>
        <geometry>
          <box>
            <size>0.025049999999999999 0.089999999999999997 0.025000000000000001</size>
          </box>
        </geometry>
        <surface>
          <contact>
            <ode>
              <kp>10000000000000</kp>
              <kd>1</kd>
            </ode>
          </contact>
          <friction>
            <ode>
              <mu2>1</mu2>
              <fdir1>0 0 0</fdir1>
            </ode>
          </friction>
        </surface>
      </collision>
      <visual name='ur_wrist_3_link_visual'>
        <pose>0 0 -0.098900000000000002 1.5707963267948959 0 0</pose>
        <geometry>
          <mesh>
            <scale>1 1 1</scale>
            <uri>file:///home/t_b/ros2_ws/src/UR-MiR-mobile-manipulator/install/ur_description/share/ur_description/meshes/ur5e/visual/wrist3.dae</uri>
          </mesh>
        </geometry>
      </visual>
      <visual name='ur_wrist_3_link_fixed_joint_lump__camera_mount_visual_1'>
        <pose>0.049999999999999989 0.029999999999999999 0.035000000000000017 -1.570796326794897 1.876254158470614e-16 -3.1415926535897931</pose>
        <geometry>
          <mesh>
            <scale>0.001 0.001 0.001</scale>
            <uri>model://mir_description/meshes/visual/D435i_mounted.STL</uri>
          </mesh>
        </geometry>
        <material>
          <diffuse>0.75000006 0.75000006 0.75000006 1</diffuse>
          <ambient>0.75000006 0.75000006 0.75000006 1</ambient>
        </material>
      </visual>
      <visual name='ur_wrist_3_link_fixed_joint_lump__realsense_link_visual_2'>
        <pose>1.387778780781446e-17 -0.07350000000000001 0.034899999999999987 -3.3306690738754701e-16 -5.5511151231257827e-17 -3.1415926535897931</pose>
        <geometry>
          <mesh>
            <scale>1 1 1</scale>
            <uri>file:///home/t_b/ros2_ws/src/UR-MiR-mobile-manipulator/install/realsense2_description/share/realsense2_description/meshes/d435.dae</uri>
          </mesh>
        </geometry>
      </visual>
      <self_collide>false</self_collide>
      <enable_wind>false</enable_wind>
      <kinematic>false</kinematic>
      <sensor name='realsensecolor' type='camera'>
        <camera name='realsense'>
          <horizontal_fov>1.2112585008840648</horizontal_fov>
          <image>
            <width>1920</width>
            <height>1080</height>
            <format>RGB_INT8</format>
          </image>
          <clip>
            <near>0.10000000000000001</near>
            <far>100</far>
          </clip>
          <noise>
            <type>gaussian</type>
            <mean>0</mean>
            <stddev>0.0070000000000000001</stddev>
          </noise>
        </camera>
        <always_on>true</always_on>
        <update_rate>30</update_rate>
        <visualize>true</visualize>
        <pose>-0.017500000000000002 -0.073499999999999996 0.030599999999999999 -3.1415926535746808 -1.5707926536057681 -1.5708026536095716</pose>
      </sensor>
      <sensor name='realsenseired1' type='camera'>
        <camera name='realsense'>
          <horizontal_fov>1.4870205226991688</horizontal_fov>
          <image>
            <width>848</width>
            <height>480</height>
            <format>L_INT8</format>
          </image>
          <clip>
            <near>0.10000000000000001</near>
            <far>100</far>
          </clip>
          <noise>
            <type>gaussian</type>
            <mean>0</mean>
            <stddev>0.050000000000000003</stddev>
          </noise>
        </camera>
        <always_on>true</always_on>
        <update_rate>60</update_rate>
        <visualize>false</visualize>
        <pose>-0.017500000000000002 -0.073499999999999996 0.030599999999999999 -3.1415926535746808 -1.5707926536057681 -1.5708026536095716</pose>
      </sensor>
      <sensor name='realsenseired2' type='camera'>
        <camera name='realsense'>
          <horizontal_fov>1.4870205226991688</horizontal_fov>
          <image>
            <width>848</width>
            <height>480</height>
            <format>L_INT8</format>
          </image>
          <clip>
            <near>0.10000000000000001</near>
            <far>100</far>
          </clip>
          <noise>
            <type>gaussian</type>
            <mean>0</mean>
            <stddev>0.050000000000000003</stddev>
          </noise>
        </camera>
        <always_on>true</always_on>
        <update_rate>60</update_rate>
        <visualize>false</visualize>
        <pose>-0.017500000000000002 -0.073499999999999996 0.030599999999999999 -3.1415926535746808 -1.5707926536057681 -1.5708026536095716</pose>
      </sensor>
      <sensor name='realsensedepth' type='depth'>
        <camera name='realsense'>
          <horizontal_fov>1.4870205226991688</horizontal_fov>
          <image>
            <width>848</width>
            <height>480</height>
          </image>
          <clip>
            <near>0.10000000000000001</near>
            <far>100</far>
          </clip>
          <noise>
            <type>gaussian</type>
            <mean>0</mean>
            <stddev>0.10000000000000001</stddev>
          </noise>
        </camera>
        <always_on>true</always_on>
        <update_rate>60</update_rate>
        <visualize>false</visualize>
        <pose>-0.017500000000000002 -0.073499999999999996 0.030599999999999999 -3.1415926535746808 -1.5707926536057681 -1.5708026536095716</pose>
      </sensor>
      <sensor name='realsenseimu' type='imu'>
        <always_on>true</always_on>
        <update_rate>200</update_rate>
        <topic>__default_topic__</topic>
        <plugin name='realsenseimu' filename='libgazebo_ros_imu_sensor.so'>
          <ros>
            <namespace>/camera</namespace>
            <remapping>~/out:=imu</remapping>
          </ros>
          <bodyName>realsense_link</bodyName>
          <frameName>realsense_gyro_optical_frame</frameName>
          <updateRateHZ>200</updateRateHZ>
          <gaussianNoise>0.1</gaussianNoise>
          <xyzOffset>0 0 0</xyzOffset>
          <rpyOffset>0 0 0</rpyOffset>
        </plugin>
        <pose>-0.017500000000000002 -0.073499999999999996 0.030599999999999999 -3.1415926535746808 -1.5707926536057681 -1.5708026536095716</pose>
        <imu/>
      </sensor>
    </link>
    <plugin name='camera' filename='librealsense_gazebo_plugin.so'>
      <prefix>realsense</prefix>
      <colorUpdateRate>30</colorUpdateRate>
      <colorTopicName>camera/color/image_raw</colorTopicName>
      <colorOpticalframeName>realsense_color_optical_frame</colorOpticalframeName>
      <colorCameraInfoTopicName>color/camera_info</colorCameraInfoTopicName>
      <infraredUpdateRate>60</infraredUpdateRate>
      <infrared1TopicName>camera/infra1/image_rect_raw</infrared1TopicName>
      <infrared2TopicName>camera/infra2/image_rect_raw</infrared2TopicName>
      <infrared1CameraInfoTopicName>camera/infra1/camera_info</infrared1CameraInfoTopicName>
      <infrared2CameraInfoTopicName>camera/infra2/camera_info</infrared2CameraInfoTopicName>
      <infrared1OpticalframeName>realsense_left_ir_optical_frame</infrared1OpticalframeName>
      <infrared2OpticalframeName>realsense_right_ir_optical_frame</infrared2OpticalframeName>
      <rangeMinDepth>0.2</rangeMinDepth>
      <rangeMaxDepth>10.0</rangeMaxDepth>
      <depthUpdateRate>60</depthUpdateRate>
      <depthTopicName>camera/depth/image_rect_raw</depthTopicName>
      <depthCameraInfoTopicName>camera/depth/camera_info</depthCameraInfoTopicName>
      <depthOpticalframeName>realsense_depth_optical_frame</depthOpticalframeName>
      <pointCloud>True</pointCloud>
      <pointCloudTopicName>depth/color/points</pointCloudTopicName>
      <pointCloudCutoff>0.5</pointCloudCutoff>
    </plugin>
    <plugin name='gz_ros2_control::GazeboSimROS2ControlPlugin' filename='gz_ros2_control-system'>
      <parameters>/home/t_b/ros2_ws/src/UR-MiR-mobile-manipulator/install/mir_description/share/mir_description/config/ros2_controllers.yaml</parameters>
      <ros>
        <remapping>/controller_manager/robot_description:=/robot_description</remapping>
      </ros>
    </plugin>
    <frame name='base_link_surface_joint' attached_to='base_link'>
      <pose>-0.0044850000000000003 0 0.35199999999999998 0 0 0</pose>
    </frame>
    <frame name='surface' attached_to='base_link_surface_joint'>
      <pose>0 0 0 0 0 0</pose>
    </frame>
    <frame name='base_link_to_back_laser_joint' attached_to='base_link'>
      <pose>-0.31640000000000001 -0.2064 0.19139999999999999 0 0 -2.3561944901923448</pose>
    </frame>
    <frame name='back_laser_link' attached_to='base_link_to_back_laser_joint'>
      <pose>0 0 0 0 0 0</pose>
    </frame>
    <frame name='base_link_to_front_laser_joint' attached_to='base_link'>
      <pose>0.31640000000000001 0.2064 0.19139999999999999 0 0 0.78539816339744839</pose>
    </frame>
    <frame name='front_laser_link' attached_to='base_link_to_front_laser_joint'>
      <pose>0 0 0 0 0 0</pose>
    </frame>
    <frame name='imu_link_to_imu_frame_joint' attached_to='imu_link'>
      <pose>0 0 0 0 0 0</pose>
    </frame>
    <frame name='imu_frame' attached_to='imu_link_to_imu_frame_joint'>
      <pose>0 0 0 0 0 0</pose>
    </frame>
    <frame name='base_link_to_imu_joint' attached_to='base_link'>
      <pose>0 0 0.25 0 0 0</pose>
    </frame>
    <frame name='imu_link' attached_to='base_link_to_imu_joint'>
      <pose>0 0 0 0 0 0</pose>
    </frame>
    <frame name='base_link_to_virtual_laser_joint' attached_to='base_link'>
      <pose>0 0 0.25 0 0 0</pose>
    </frame>
    <frame name='virtual_laser_link' attached_to='base_link_to_virtual_laser_joint'>
      <pose>0 0 0 0 0 0</pose>
    </frame>
    <frame name='power_unit_joint' attached_to='base_link'>
      <pose>0 0 0.29999999999999999 0 0 0</pose>
    </frame>
    <frame name='power_unit' attached_to='power_unit_joint'>
      <pose>0 0 0 0 0 0</pose>
    </frame>
    <frame name='ur_base_link-base_fixed_joint' attached_to='ur_base_link'>
      <pose>0 0 0 0 0 3.1415926535897931</pose>
    </frame>
    <frame name='ur_base' attached_to='ur_base_link-base_fixed_joint'>
      <pose>0 0 0 0 0 0</pose>
    </frame>
    <frame name='ur_base_link-base_link_inertia' attached_to='ur_base_link'>
      <pose>0 0 0 0 0 3.1415926535897931</pose>
    </frame>
    <frame name='ur_base_link_inertia' attached_to='ur_base_link-base_link_inertia'>
      <pose>0 0 0 0 0 0</pose>
    </frame>
    <frame name='camera_mount_joint' attached_to='ur_flange'>
      <pose>0.035000000000000003 0.050000000000000003 0.029999999999999999 3.1415926535897931 1.2246467991473532e-16 -1.570796326794897</pose>
    </frame>
    <frame name='camera_mount' attached_to='camera_mount_joint'>
      <pose>0 0 0 0 0 0</pose>
    </frame>
    <frame name='realsense_accel_optical_joint' attached_to='realsense_accel_frame'>
      <pose>0 0 0 -1.5707963267948959 -5.5511151231257827e-17 -1.5707963267948959</pose>
    </frame>
    <frame name='realsense_accel_optical_frame' attached_to='realsense_accel_optical_joint'>
      <pose>0 0 0 0 0 0</pose>
    </frame>
    <frame name='realsense_accel_joint' attached_to='realsense_link'>
      <pose>-0.01174 -0.0055199999999999997 0.0051000000000000004 0 0 0</pose>
    </frame>
    <frame name='realsense_accel_frame' attached_to='realsense_accel_joint'>
      <pose>0 0 0 0 0 0</pose>
    </frame>
    <frame name='realsense_color_optical_joint' attached_to='realsense_color_frame'>
      <pose>0 0 0 -1.5707963267948959 -5.5511151231257827e-17 -1.5707963267948959</pose>
    </frame>
    <frame name='realsense_color_optical_frame' attached_to='realsense_color_optical_joint'>
      <pose>0 0 0 0 0 0</pose>
    </frame>
    <frame name='realsense_color_joint' attached_to='realsense_link'>
      <pose>0 0.014999999999999999 0 0 0 0</pose>
    </frame>
    <frame name='realsense_color_frame' attached_to='realsense_color_joint'>
      <pose>0 0 0 0 0 0</pose>
    </frame>
    <frame name='realsense_depth_optical_joint' attached_to='realsense_depth_frame'>
      <pose>0 0 0 -1.5707963267948959 -5.5511151231257827e-17 -1.5707963267948959</pose>
    </frame>
    <frame name='realsense_depth_optical_frame' attached_to='realsense_depth_optical_joint'>
      <pose>0 0 0 0 0 0</pose>
    </frame>
    <frame name='realsense_depth_joint' attached_to='realsense_link'>
      <pose>0 0 0 0 0 0</pose>
    </frame>
    <frame name='realsense_depth_frame' attached_to='realsense_depth_joint'>
      <pose>0 0 0 0 0 0</pose>
    </frame>
    <frame name='realsense_gyro_optical_joint' attached_to='realsense_gyro_frame'>
      <pose>0 0 0 -1.5707963267948959 -5.5511151231257827e-17 -1.5707963267948959</pose>
    </frame>
    <frame name='realsense_gyro_optical_frame' attached_to='realsense_gyro_optical_joint'>
      <pose>0 0 0 0 0 0</pose>
    </frame>
    <frame name='realsense_gyro_joint' attached_to='realsense_link'>
      <pose>-0.01174 -0.0055199999999999997 0.0051000000000000004 0 0 0</pose>
    </frame>
    <frame name='realsense_gyro_frame' attached_to='realsense_gyro_joint'>
      <pose>0 0 0 0 0 0</pose>
    </frame>
    <frame name='realsense_infra1_optical_joint' attached_to='realsense_infra1_frame'>
      <pose>0 0 0 -1.5707963267948959 -5.5511151231257827e-17 -1.5707963267948959</pose>
    </frame>
    <frame name='realsense_infra1_optical_frame' attached_to='realsense_infra1_optical_joint'>
      <pose>0 0 0 0 0 0</pose>
    </frame>
    <frame name='realsense_infra1_joint' attached_to='realsense_link'>
      <pose>0 0 0 0 0 0</pose>
    </frame>
    <frame name='realsense_infra1_frame' attached_to='realsense_infra1_joint'>
      <pose>0 0 0 0 0 0</pose>
    </frame>
    <frame name='realsense_infra2_optical_joint' attached_to='realsense_infra2_frame'>
      <pose>0 0 0 -1.5707963267948959 -5.5511151231257827e-17 -1.5707963267948959</pose>
    </frame>
    <frame name='realsense_infra2_optical_frame' attached_to='realsense_infra2_optical_joint'>
      <pose>0 0 0 0 0 0</pose>
    </frame>
    <frame name='realsense_infra2_joint' attached_to='realsense_link'>
      <pose>0 -0.050000000000000003 0 0 0 0</pose>
    </frame>
    <frame name='realsense_infra2_frame' attached_to='realsense_infra2_joint'>
      <pose>0 0 0 0 0 0</pose>
    </frame>
    <frame name='realsense_link_joint' attached_to='realsense_bottom_screw_frame'>
      <pose>0.0106 0.017500000000000002 0.012500000000000001 0 0 0</pose>
    </frame>
    <frame name='realsense_link' attached_to='realsense_link_joint'>
      <pose>0 0 0 0 0 0</pose>
    </frame>
    <frame name='realsense_joint' attached_to='ur_flange'>
      <pose>0.02 0 -0.060999999999999999 3.1415926535897931 0 0</pose>
    </frame>
    <frame name='realsense_bottom_screw_frame' attached_to='realsense_joint'>
      <pose>0 0 0 0 0 0</pose>
    </frame>
    <frame name='ur_flange-tool0' attached_to='ur_flange'>
      <pose>0 0 0 1.5707963267948959 -5.5511151231257827e-17 1.5707963267948959</pose>
    </frame>
    <frame name='ur_tool0' attached_to='ur_flange-tool0'>
      <pose>0 0 0 0 0 0</pose>
    </frame>
    <frame name='ur_wrist_3-flange' attached_to='ur_wrist_3_link'>
      <pose>0 0 0 -1.5707963267948957 -1.5707963267948966 0</pose>
    </frame>
    <frame name='ur_flange' attached_to='ur_wrist_3-flange'>
      <pose>0 0 0 0 0 0</pose>
    </frame>
    <frame name='ur_wrist_3_link-ft_frame' attached_to='ur_wrist_3_link'>
      <pose>0 0 0 3.1415926535897931 0 0</pose>
    </frame>
    <frame name='ur_ft_frame' attached_to='ur_wrist_3_link-ft_frame'>
      <pose>0 0 0 0 0 0</pose>
    </frame>
    <frame name='ur_base_joint' attached_to='base_link'>
      <pose>0.13500000000000001 0 0.79000000000000004 0 0 1.5707963267948959</pose>
    </frame>
    <frame name='ur_base_link' attached_to='ur_base_joint'>
      <pose>0 0 0 0 0 0</pose>
    </frame>
    <frame name='us_1_joint' attached_to='base_link'>
      <pose>0.45000000000000001 -0.12 0.16 0 0 0</pose>
    </frame>
    <frame name='us_1_frame' attached_to='us_1_joint'>
      <pose>0 0 0 0 0 0</pose>
    </frame>
    <frame name='us_2_joint' attached_to='base_link'>
      <pose>0.45000000000000001 0.12 0.16 0 0 0</pose>
    </frame>
    <frame name='us_2_frame' attached_to='us_2_joint'>
      <pose>0 0 0 0 0 0</pose>
    </frame>
    <frame name='world_joint' attached_to='base_link'>
      <pose>0.13500000000000001 0 0.79000000000000004 0 0 1.5707963267948959</pose>
    </frame>
    <frame name='world' attached_to='world_joint'>
      <pose>0 0 0 0 0 0</pose>
    </frame>
    <frame name='base_joint' attached_to='base_footprint'>
      <pose>0 0 0 0 0 0</pose>
    </frame>
    <frame name='base_link' attached_to='base_joint'>
      <pose>0 0 0 0 0 0</pose>
    </frame>
  </model>
</sdf>
